Workbook

Sheet ORB Results
A1: Date | B1: Day_of_Week | C1: Symbol | D1: Range_High | E1: Range_Low | F1: Range | G1: Trade_Direction | H1: Entry_Price | I1: Exit_Price | J1: Trade_PL | K1: Drawdown_Pct | L1: Result | M1: Cumulative_PL
A2: 2021-03-04 | B2: Thursday | C2: MNQH1 | D2: 12765 | E2: 12649.5 | F2: =D2-E2 | G2: Short | H2: 12649.5 | I2: 12534 | J2: =IF(G2="Long",I2-H2,IF(G2="Short",H2-I2,0)) | K2: 0 | L2: Win | M2: =J2
A3: 2021-03-04 | B3: Thursday | C3: MNQH1 | D3: 12765 | E3: 12649.5 | F3: =D3-E3 | G3: Short | H3: 12649.5 | I3: 12765 | J3: =IF(G3="Long",I3-H3,IF(G3="Short",H3-I3,0)) | K3: 100 | L3: Loss | M3: =M2+J3
A4: 2021-03-05 | B4: Friday | C4: MNQH1 | D4: 12606 | E4: 12446.25 | F4: =D4-E4 | G4: Short | H4: 12446.25 | I4: 12286.5 | J4: =IF(G4="Long",I4-H4,IF(G4="Short",H4-I4,0)) | K4: 29.26 | L4: Win | M4: =M3+J4
A5: 2021-03-05 | B5: Friday | C5: MNQH1 | D5: 12606 | E5: 12446.25 | F5: =D5-E5 | G5: Short | H5: 12446.25 | I5: 12606 | J5: =IF(G5="Long",I5-H5,IF(G5="Short",H5-I5,0)) | K5: 100 | L5: Loss | M5: =M4+J5
A6: 2021-03-08 | B6: Monday | C6: MNQH1 | D6: 12686 | E6: 12526.5 | F6: =D6-E6 | G6: Long | H6: 12686 | I6: 12526.5 | J6: =IF(G6="Long",I6-H6,IF(G6="Short",H6-I6,0)) | K6: 100 | L6: Loss | M6: =M5+J6
A7: 2021-03-08 | B7: Monday | C7: MNQH1 | D7: 12686 | E7: 12526.5 | F7: =D7-E7 | G7: Short | H7: 12526.5 | I7: 12367 | J7: =IF(G7="Long",I7-H7,IF(G7="Short",H7-I7,0)) | K7: 38.71 | L7: Win | M7: =M6+J7
A8: 2021-03-09 | B8: Tuesday | C8: MNQH1 | D8: 12652.25 | E8: 12587 | F8: =D8-E8 | G8: Long | H8: 12652.25 | I8: 12717.5 | J8: =IF(G8="Long",I8-H8,IF(G8="Short",H8-I8,0)) | K8: 15.33 | L8: Win | M8: =M7+J8
A9: 2021-03-10 | B9: Wednesday | C9: MNQH1 | D9: 12969.25 | E9: 12870.25 | F9: =D9-E9 | G9: Short | H9: 12870.25 | I9: 12771.25 | J9: =IF(G9="Long",I9-H9,IF(G9="Short",H9-I9,0)) | K9: 0 | L9: Win | M9: =M8+J9
A10: 2021-03-11 | B10: Thursday | C10: MNQH1 | D10: 13006.75 | E10: 12931.75 | F10: =D10-E10 | G10: Short | H10: 12931.75 | I10: 13006.75 | J10: =IF(G10="Long",I10-H10,IF(G10="Short",H10-I10,0)) | K10: 100 | L10: Loss | M10: =M9+J10
A11: 2021-03-11 | B11: Thursday | C11: MNQH1 | D11: 13006.75 | E11: 12931.75 | F11: =D11-E11 | G11: Long | H11: 13006.75 | I11: 13081.75 | J11: =IF(G11="Long",I11-H11,IF(G11="Short",H11-I11,0)) | K11: 18.33 | L11: Win | M11: =M10+J11
A12: 2021-03-12 | B12: Friday | C12: MNQM1 | D12: 12865.25 | E12: 12789 | F12: =D12-E12 | G12: Long | H12: 12865.25 | I12: 12789 | J12: =IF(G12="Long",I12-H12,IF(G12="Short",H12-I12,0)) | K12: 100 | L12: Loss | M12: =M11+J12
A13: 2021-03-12 | B13: Friday | C13: MNQM1 | D13: 12865.25 | E13: 12789 | F13: =D13-E13 | G13: Short | H13: 12789 | I13: 12865.25 | J13: =IF(G13="Long",I13-H13,IF(G13="Short",H13-I13,0)) | K13: 100 | L13: Loss | M13: =M12+J13
A14: 2021-03-15 | B14: Monday | C14: MNQM1 | D14: 12941.5 | E14: 12887.5 | F14: =D14-E14 | G14: Long | H14: 12941.5 | I14: 12887.5 | J14: =IF(G14="Long",I14-H14,IF(G14="Short",H14-I14,0)) | K14: 100 | L14: Loss | M14: =M13+J14
... A634: 2022-10-11 | B634: Tuesday | C634: MNQZ2 | D634: 10944.5 | E634: 10859.5 | F634: =D634-E634 | G634: Long | H634: 10944.5 | I634: 11029.5 | J634: =IF(G634="Long",I634-H634,IF(G634="Short",H634-I634,0)) | K634: 37.06 | L634: Win | M634: =M633+J634
A635: 2022-10-12 | B635: Wednesday | C635: MNQZ2 | D635: 10932 | E635: 10805.75 | F635: =D635-E635 | G635: No-Op | J635: =IF(G635="Long",I635-H635,IF(G635="Short",H635-I635,0)) | K635: 0 | L635: No-Op | M635: =M634+J635
A636: 2022-10-13 | B636: Thursday | C636: MNQZ2 | D636: 10554.25 | E636: 10484.5 | F636: =D636-E636 | G636: Long | H636: 10554.25 | I636: 10624 | J636: =IF(G636="Long",I636-H636,IF(G636="Short",H636-I636,0)) | K636: 0 | L636: Win | M636: =M635+J636
A637: 2022-10-14 | B637: Friday | C637: MNQZ2 | D637: 11207.75 | E637: 11099.25 | F637: =D637-E637 | G637: Short | H637: 11099.25 | I637: 10990.75 | J637: =IF(G637="Long",I637-H637,IF(G637="Short",H637-I637,0)) | K637: 0 | L637: Win | M637: =M636+J637
A638: 2022-10-17 | B638: Monday | C638: MNQZ2 | D638: 11114.25 | E638: 10999 | F638: =D638-E638 | G638: Long | H638: 11114.25 | I638: 11110.75 | J638: =IF(G638="Long",I638-H638,IF(G638="Short",H638-I638,0)) | K638: 79.61 | L638: EOD-Close | M638: =M637+J638
A639: 2022-10-18 | B639: Tuesday | C639: MNQZ2 | D639: 11431.75 | E639: 11346.75 | F639: =D639-E639 | G639: Short | H639: 11346.75 | I639: 11261.75 | J639: =IF(G639="Long",I639-H639,IF(G639="Short",H639-I639,0)) | K639: 0 | L639: Win | M639: =M638+J639
A640: 2022-10-19 | B640: Wednesday | C640: MNQZ2 | D640: 11213.25 | E640: 11110.25 | F640: =D640-E640 | G640: Long | H640: 11213.25 | I640: 11110.25 | J640: =IF(G640="Long",I640-H640,IF(G640="Short",H640-I640,0)) | K640: 100 | L640: Loss | M640: =M639+J640
A641: 2022-10-19 | B641: Wednesday | C641: MNQZ2 | D641: 11213.25 | E641: 11110.25 | F641: =D641-E641 | G641: Short | H641: 11110.25 | I641: 11154.75 | J641: =IF(G641="Long",I641-H641,IF(G641="Short",H641-I641,0)) | K641: 46.84 | L641: EOD-Close | M641: =M640+J641
A642: 2022-10-20 | B642: Thursday | C642: MNQZ2 | D642: 11165 | E642: 11091.5 | F642: =D642-E642 | G642: Long | H642: 11165 | I642: 11238.5 | J642: =IF(G642="Long",I642-H642,IF(G642="Short",H642-I642,0)) | K642: 0 | L642: Win | M642: =M641+J642
A643: 2022-10-20 | B643: Thursday | C643: MNQZ2 | D643: 11165 | E643: 11091.5 | F643: =D643-E643 | G643: Long | H643: 11165 | I643: 11091.5 | J643: =IF(G643="Long",I643-H643,IF(G643="Short",H643-I643,0)) | K643: 100 | L643: Loss | M643: =M642+J643
A644: 2022-10-21 | B644: Friday | C644: MNQZ2 | D644: 11088.25 | E644: 10994.75 | F644: =D644-E644 | G644: Long | H644: 11088.25 | I644: 11181.75 | J644: =IF(G644="Long",I644-H644,IF(G644="Short",H644-I644,0)) | K644: 24.33 | L644: Win | M644: =M643+J644
A645: 2022-10-21 | B645: Friday | C645: MNQZ2 | D645: 11088.25 | E645: 10994.75 | F645: =D645-E645 | G645: Long | H645: 11088.25 | I645: 11181.75 | J645: =IF(G645="Long",I645-H645,IF(G645="Short",H645-I645,0)) | K645: 39.84 | L645: Win | M645: =M644+J645
A646: 2022-10-24 | B646: Monday | C646: MNQZ2 | D646: 11398.5 | E646: 11300.25 | F646: =D646-E646 | G646: Short | H646: 11300.25 | I646: 11398.5 | J646: =IF(G646="Long",I646-H646,IF(G646="Short",H646-I646,0)) | K646: 100 | L646: Loss | M646: =M645+J646
A647: 2022-10-24 | B647: Monday | C647: MNQZ2 | D647: 11398.5 | E647: 11300.25 | F647: =D647-E647 | G647: Long | H647: 11398.5 | I647: 11496.75 | J647: =IF(G647="Long",I647-H647,IF(G647="Short",H647-I647,0)) | K647: 25.7 | L647: Win | M647: =M646+J647
... A1911: 2025-11-26 | B1911: Wednesday | C1911: MNQZ5 | D1911: 25271 | E1911: 25189.25 | F1911: =D1911-E1911 | G1911: Long | H1911: 25271 | I1911: 25352.75 | J1911: =IF(G1911="Long",I1911-H1911,IF(G1911="Short",H1911-I1911,0)) | K1911: 0 | L1911: Win | M1911: =M1910+J1911
A1912: 2025-11-27 | B1912: Thursday | C1912: MNQZ5 | D1912: 25318 | E1912: 25287 | F1912: =D1912-E1912 | G1912: No-Op | J1912: =IF(G1912="Long",I1912-H1912,IF(G1912="Short",H1912-I1912,0)) | K1912: 0 | L1912: No-Op | M1912: =M1911+J1912
A1913: 2025-11-28 | B1913: Friday | C1913: MNQZ5 | D1913: 25421.5 | E1913: 25329.5 | F1913: =D1913-E1913 | G1913: Long | H1913: 25421.5 | I1913: 25484.75 | J1913: =IF(G1913="Long",I1913-H1913,IF(G1913="Short",H1913-I1913,0)) | K1913: 58.7 | L1913: EOD-Close | M1913: =M1912+J1913
A1914: 2025-12-01 | B1914: Monday | C1914: MNQZ5 | D1914: 25319.75 | E1914: 25209 | F1914: =D1914-E1914 | G1914: Long | H1914: 25319.75 | I1914: 25430.5 | J1914: =IF(G1914="Long",I1914-H1914,IF(G1914="Short",H1914-I1914,0)) | K1914: 48.31 | L1914: Win | M1914: =M1913+J1914
A1915: 2025-12-02 | B1915: Tuesday | C1915: MNQZ5 | D1915: 25613 | E1915: 25471.25 | F1915: =D1915-E1915 | G1915: Long | H1915: 25613 | I1915: 25471.25 | J1915: =IF(G1915="Long",I1915-H1915,IF(G1915="Short",H1915-I1915,0)) | K1915: 100 | L1915: Loss | M1915: =M1914+J1915
A1916: 2025-12-02 | B1916: Tuesday | C1916: MNQZ5 | D1916: 25613 | E1916: 25471.25 | F1916: =D1916-E1916 | G1916: Short | H1916: 25471.25 | I1916: 25613 | J1916: =IF(G1916="Long",I1916-H1916,IF(G1916="Short",H1916-I1916,0)) | K1916: 100 | L1916: Loss | M1916: =M1915+J1916
A1917: 2025-12-03 | B1917: Wednesday | C1917: MNQZ5 | D1917: 25538 | E1917: 25451.5 | F1917: =D1917-E1917 | G1917: Long | H1917: 25538 | I1917: 25624.5 | J1917: =IF(G1917="Long",I1917-H1917,IF(G1917="Short",H1917-I1917,0)) | K1917: 46.24 | L1917: Win | M1917: =M1916+J1917
A1918: 2025-12-04 | B1918: Thursday | C1918: MNQZ5 | D1918: 25713.25 | E1918: 25550.5 | F1918: =D1918-E1918 | G1918: Short | H1918: 25550.5 | I1918: 25627.5 | J1918: =IF(G1918="Long",I1918-H1918,IF(G1918="Short",H1918-I1918,0)) | K1918: 63.75 | L1918: EOD-Close | M1918: =M1917+J1918
A1919: 2025-12-05 | B1919: Friday | C1919: MNQZ5 | D1919: 25777.75 | E1919: 25660.5 | F1919: =D1919-E1919 | G1919: Long | H1919: 25777.75 | I1919: 25660.5 | J1919: =IF(G1919="Long",I1919-H1919,IF(G1919="Short",H1919-I1919,0)) | K1919: 100 | L1919: Loss | M1919: =M1918+J1919
A1920: 2025-12-08 | B1920: Monday | C1920: MNQZ5 | D1920: 25860.75 | E1920: 25768 | F1920: =D1920-E1920 | G1920: Short | H1920: 25768 | I1920: 25675.25 | J1920: =IF(G1920="Long",I1920-H1920,IF(G1920="Short",H1920-I1920,0)) | K1920: 14.29 | L1920: Win | M1920: =M1919+J1920
A1921: 2025-12-09 | B1921: Tuesday | C1921: MNQZ5 | D1921: 25653.25 | E1921: 25560 | F1921: =D1921-E1921 | G1921: Long | H1921: 25653.25 | I1921: 25703 | J1921: =IF(G1921="Long",I1921-H1921,IF(G1921="Short",H1921-I1921,0)) | K1921: 19.03 | L1921: EOD-Close | M1921: =M1920+J1921
A1922: 2025-12-10 | B1922: Wednesday | C1922: MNQZ5 | D1922: 25663.25 | E1922: 25567 | F1922: =D1922-E1922 | G1922: Short | H1922: 25567 | I1922: 25663.25 | J1922: =IF(G1922="Long",I1922-H1922,IF(G1922="Short",H1922-I1922,0)) | K1922: 100 | L1922: Loss | M1922: =M1921+J1922
...

Sheet Summary
A1: Metric | B1: Value
A2: Total Rows | B2: =COUNTA('ORB Results'!L2:L2059)
A3: Trades (excl No-Op) | B3: =COUNTIF('ORB Results'!L2:L2059,"Win")+COUNTIF('ORB Results'!L2:L2059,"Loss")+COUNTIF('ORB Results'!L2:L2059,"EOD-Close")+COUNTIF('ORB Results'!L2:L2059,"Period-Close")
A4: Wins | B4: =COUNTIF('ORB Results'!L2:L2059,"Win")
A5: Losses | B5: =COUNTIF('ORB Results'!L2:L2059,"Loss")
A6: EOD/Period Close | B6: =COUNTIF('ORB Results'!L2:L2059,"EOD-Close")+COUNTIF('ORB Results'!L2:L2059,"Period-Close")
A7: No-Op | B7: =COUNTIF('ORB Results'!L2:L2059,"No-Op")
A8: Win Rate (W/L only) | B8: =IF(B4+B5>0,B4/(B4+B5),0)
A9: Win Rate (all trades) | B9: =IF(B3>0,COUNTIFS('ORB Results'!L2:L2059,"<>No-Op",'ORB Results'!J2:J2059,">"&0)/B3,0)
A10: Total P/L | B10: =SUM('ORB Results'!J2:J2059)
A11: Avg Trade P/L | B11: =IF(B3>0,B10/B3,0)
A12: Avg Drawdown % | B12: =AVERAGEIFS('ORB Results'!K2:K2059,'ORB Results'!L2:L2059,"<>No-Op")
A13: Avg Win Drawdown % | B13: =AVERAGEIF('ORB Results'!L2:L2059,"Win",'ORB Results'!K2:K2059)
A14: Final Cumulative P/L | B14: ='ORB Results'!M2059
